Workbook
Name Slicer_Month: #N/A

Sheet DATA
A1: Month | B1: Transaction Number | C1: Product Code | D1: Product Description | E1: Store Cost | F1: Sale Price | G1: Profit | H1: Commision 10% | I1: First Name | J1: Last Name | K1: Sale Location
A2: Jan | B2: 1001 | C2: 9822 | D2: Pool Cover | E2: 58.3 | F2: 98.4 | G2: =F2-E2 -> 40.1 | H2: =IF(F2>50,G2*0.2,G2*0.1) -> 8.02 | I2: Chalie | J2: Barns | K2: NM
A3: Jan | B3: 1002 | C3: 2877 | D3: Net | E3: 11.4 | F3: 16.3 | G3: =F3-E3 -> 4.9 | H3: =IF(F3>50,G3*0.2,G3*0.1) -> 0.49 | I3: Juan | J3: Hernandez | K3: CA
A4: Jan | B4: 1003 | C4: 2499 | D4: 8 ft Hose | E4: 6.2 | F4: 9.2 | G4: =F4-E4 -> 3 | H4: =IF(F4>50,G4*0.2,G4*0.1) -> 0.3 | I4: Doug | J4: Smith | K4: AZ
A5: Jan | B5: 1004 | C5: 8722 | D5: Water Pump | E5: 344 | F5: 502 | G5: =F5-E5 -> 158 | H5: =IF(F5>50,G5*0.2,G5*0.1) -> 31.6 | I5: Chalie | J5: Barns | K5: AZ
A6: Jan | B6: 1005 | C6: 1109 | D6: Chlorine Test Kit | E6: 3 | F6: 8 | G6: =F6-E6 -> 5 | H6: =IF(F6>50,G6*0.2,G6*0.1) -> 0.5 | I6: Doug | J6: Smith | K6: AZ
A7: Jan | B7: 1006 | C7: 9822 | D7: Pool Cover | E7: 58.3 | F7: 98.4 | G7: =F7-E7 -> 40.1 | H7: =IF(F7>50,G7*0.2,G7*0.1) -> 8.02 | I7: Doug | J7: Smith | K7: AZ
A8: Jan | B8: 1007 | C8: 1109 | D8: Chlorine Test Kit | E8: 3 | F8: 8 | G8: =F8-E8 -> 5 | H8: =IF(F8>50,G8*0.2,G8*0.1) -> 0.5 | I8: Hellen | J8: Johnson | K8: NM
A9: Jan | B9: 1008 | C9: 2877 | D9: Net | E9: 11.4 | F9: 16.3 | G9: =F9-E9 -> 4.9 | H9: =IF(F9>50,G9*0.2,G9*0.1) -> 0.49 | I9: Doug | J9: Smith | K9: NM
A10: Jan | B10: 1009 | C10: 1109 | D10: Chlorine Test Kit | E10: 3 | F10: 8 | G10: =F10-E10 -> 5 | H10: =IF(F10>50,G10*0.2,G10*0.1) -> 0.5 | I10: Doug | J10: Smith | K10: AZ
A11: Jan | B11: 1010 | C11: 2877 | D11: Net | E11: 11.4 | F11: 16.3 | G11: =F11-E11 -> 4.9 | H11: =IF(F11>50,G11*0.2,G11*0.1) -> 0.49 | I11: Juan | J11: Hernandez | K11: CO
A12: Jan | B12: 1011 | C12: 2877 | D12: Net | E12: 11.4 | F12: 16.3 | G12: =F12-E12 -> 4.9 | H12: =IF(F12>50,G12*0.2,G12*0.1) -> 0.49 | I12: Juan | J12: Hernandez | K12: AZ
A13: Jan | B13: 1012 | C13: 4421 | D13: Skimmer | E13: 45 | F13: 87 | G13: =F13-E13 -> 42 | H13: =IF(F13>50,G13*0.2,G13*0.1) -> 8.4 | I13: Doug | J13: Smith | K13: NM
... A80: Jun | B80: 1079 | C80: 2877 | D80: Net | E80: 11.4 | F80: 16.3 | G80: =F80-E80 -> 4.9 | H80: =IF(F80>50,G80*0.2,G80*0.1) -> 0.49 | I80: Juan | J80: Hernandez | K80: NM
A81: Jun | B81: 1080 | C81: 4421 | D81: Skimmer | E81: 45 | F81: 87 | G81: =F81-E81 -> 42 | H81: =IF(F81>50,G81*0.2,G81*0.1) -> 8.4 | I81: Doug | J81: Smith | K81: CA | P81: =R81 -> 0
A82: Jun | B82: 1081 | C82: 6119 | D82: Algea Killer 8 oz | E82: 9 | F82: 14 | G82: =F82-E82 -> 5 | H82: =IF(F82>50,G82*0.2,G82*0.1) -> 0.5 | I82: Doug | J82: Smith | K82: UT
A83: Jun | B83: 1082 | C83: 1109 | D83: Chlorine Test Kit | E83: 3 | F83: 8 | G83: =F83-E83 -> 5 | H83: =IF(F83>50,G83*0.2,G83*0.1) -> 0.5 | I83: Chalie | J83: Barns | K83: CA
A84: Jun | B84: 1083 | C84: 1109 | D84: Chlorine Test Kit | E84: 3 | F84: 8 | G84: =F84-E84 -> 5 | H84: =IF(F84>50,G84*0.2,G84*0.1) -> 0.5 | I84: Chalie | J84: Barns | K84: NV
A85: Jun | B85: 1084 | C85: 6119 | D85: Algea Killer 8 oz | E85: 9 | F85: 14 | G85: =F85-E85 -> 5 | H85: =IF(F85>50,G85*0.2,G85*0.1) -> 0.5 | I85: Chalie | J85: Barns | K85: AZ
A86: Jun | B86: 1085 | C86: 9822 | D86: Pool Cover | E86: 58.3 | F86: 98.4 | G86: =F86-E86 -> 40.1 | H86: =IF(F86>50,G86*0.2,G86*0.1) -> 8.02 | I86: Doug | J86: Smith | K86: NV
A87: Jun | B87: 1086 | C87: 1109 | D87: Chlorine Test Kit | E87: 3 | F87: 8 | G87: =F87-E87 -> 5 | H87: =IF(F87>50,G87*0.2,G87*0.1) -> 0.5 | I87: Hellen | J87: Johnson | K87: AZ
A88: Jun | B88: 1087 | C88: 2499 | D88: 8 ft Hose | E88: 6.2 | F88: 9.2 | G88: =F88-E88 -> 3 | H88: =IF(F88>50,G88*0.2,G88*0.1) -> 0.3 | I88: Chalie | J88: Barns | K88: CA
A89: Jul | B89: 1088 | C89: 2499 | D89: 8 ft Hose | E89: 6.2 | F89: 9.2 | G89: =F89-E89 -> 3 | H89: =IF(F89>50,G89*0.2,G89*0.1) -> 0.3 | I89: Chalie | J89: Barns | K89: NM
A90: Jul | B90: 1089 | C90: 6119 | D90: Algea Killer 8 oz | E90: 9 | F90: 14 | G90: =F90-E90 -> 5 | H90: =IF(F90>50,G90*0.2,G90*0.1) -> 0.5 | I90: Doug | J90: Smith | K90: NV
A91: Jul | B91: 1090 | C91: 2877 | D91: Net | E91: 11.4 | F91: 16.3 | G91: =F91-E91 -> 4.9 | H91: =IF(F91>50,G91*0.2,G91*0.1) -> 0.49 | I91: Chalie | J91: Barns | K91: CA
A92: Jul | B92: 1091 | C92: 2877 | D92: Net | E92: 11.4 | F92: 16.3 | G92: =F92-E92 -> 4.9 | H92: =IF(F92>50,G92*0.2,G92*0.1) -> 0.49 | I92: Hellen | J92: Johnson | K92: NV
A93: Jul | B93: 1092 | C93: 2877 | D93: Net | E93: 11.4 | F93: 16.3 | G93: =F93-E93 -> 4.9 | H93: =IF(F93>50,G93*0.2,G93*0.1) -> 0.49 | I93: Doug | J93: Smith | K93: CA
... A172: Dec | B172: 1171 | C172: 4421 | D172: Skimmer | E172: 45 | F172: 87 | G172: =F172-E172 -> 42 | H172: =IF(F172>50,G172*0.2,G172*0.1) -> 8.4 | I172: Juan | J172: Hernandez | K172: NV
E175: =SUM(F2:F172) -> 17110.6 | F175: =SUM(G2:G172) -> 6356.7
G177: =(F175/E175)*100% -> 0.37150655

Sheet PivotTable
A1: TOTAL SALES | B1: =SUM(DATA!F2:F172) -> 17110.6 | D1: Total Profit | E1: =SUM(DATA!G2:G172) -> 6356.7
D2: Total Cost Price | E2: =SUM(DATA!E2:E172) -> 10753.9
A3: Average Sales | B3: =AVERAGE(DATA!F2:F172) -> 100.06199
W4: Row Labels | X4: Sum of Sale Price
A5: Sales By Product | W5: Jan | X5: 1409.5
A6: Row Labels | B6: Sum of Sale Price | W6: Feb | X6: 841.4
A7: 1 Gal Muratic Acid | B7: 77 | W7: Mar | X7: 1421.4
A8: 5 Gal Chlorine | B8: 693 | W8: Apr | X8: 1089.7
A9: 8 ft Hose | B9: 184 | W9: May | X9: 214.4
A10: Algea Killer 8 oz | B10: 210 | W10: Jun | X10: 409.9
A11: AutoVac | B11: 1984 | W11: Jul | X11: 186.1
A12: Chlorine Test Kit | B12: 160 | W12: Aug | X12: 2253
A13: Net | B13: 391.2 | W13: Sep | X13: 2508.2
A14: Pool Cover | B14: 2066.4 | W14: Oct | X14: 1927.6
A15: Skimmer | B15: 1305 | W15: Nov | X15: 2473.8
A16: Water Pump | B16: 10040 | W16: Dec | X16: 2375.6
A17: Grand Total | B17: 17110.6 | W17: Grand Total | X17: 17110.6
A19: Profit Margin | B19: =DATA!G177 -> 0.37150655
A21: Product Commission
A22: Row Labels | B22: Sum of Commision 10%
A23: 1 Gal Muratic Acid | B23: 3.3
A24: 5 Gal Chlorine | B24: 63
A25: 8 ft Hose | B25: 6
A26: Algea Killer 8 oz | B26: 7.5
A27: AutoVac | B27: 204.8
A28: Chlorine Test Kit | B28: 10
A29: Net | B29: 11.76
A30: Pool Cover | B30: 168.42
A31: Skimmer | B31: 126
A32: Water Pump | B32: 632
A33: Grand Total | B33: 1232.78
A35: Profit Per City
A36: Row Labels | B36: Sum of Profit
A37: AZ | B37: 1979.1
A38: CA | B38: 1485.1
A39: CO | B39: 23.8
A40: NM | B40: 681.8
A41: NV | B41: 1710.1
A42: UT | B42: 476.8
A43: Grand Total | B43: 6356.7
...

Sheet Dashboard
